2025-06-23 20:24:12,088 ERROR: Exception on /applications [GET] [in /Users/aryan/opt/anaconda3/lib/python3.8/site-packages/flask/app.py:828]
Traceback (most recent call last):
  File "/Users/aryan/opt/anaconda3/lib/python3.8/site-packages/flask/app.py", line 1463, in wsgi_app
    response = self.full_dispatch_request()
  File "/Users/aryan/opt/anaconda3/lib/python3.8/site-packages/flask/app.py", line 872, in full_dispatch_request
    rv = self.handle_user_exception(e)
  File "/Users/aryan/opt/anaconda3/lib/python3.8/site-packages/flask/app.py", line 870, in full_dispatch_request
    rv = self.dispatch_request()
  File "/Users/aryan/opt/anaconda3/lib/python3.8/site-packages/flask/app.py", line 855, in dispatch_request
    return self.ensure_sync(self.view_functions[rule.endpoint])(**view_args)  # type: ignore[no-any-return]
  File "/Users/aryan/opt/anaconda3/lib/python3.8/site-packages/flask_login/utils.py", line 290, in decorated_view
    return current_app.ensure_sync(func)(*args, **kwargs)
  File "/Users/aryan/Documents/GitHub/job-bot-/app/routes.py", line 82, in applications
    return render_template('application/list.html', applications=applications)
  File "/Users/aryan/opt/anaconda3/lib/python3.8/site-packages/flask/templating.py", line 150, in render_template
    return _render(app, template, context)
  File "/Users/aryan/opt/anaconda3/lib/python3.8/site-packages/flask/templating.py", line 131, in _render
    rv = template.render(context)
  File "/Users/aryan/opt/anaconda3/lib/python3.8/site-packages/jinja2/environment.py", line 1301, in render
    self.environment.handle_exception()
  File "/Users/aryan/opt/anaconda3/lib/python3.8/site-packages/jinja2/environment.py", line 936, in handle_exception
    raise rewrite_traceback_stack(source=source)
  File "/Users/aryan/Documents/GitHub/job-bot-/app/templates/application/list.html", line 1, in top-level template code
    {% extends "base.html" %}
  File "/Users/aryan/Documents/GitHub/job-bot-/app/templates/base.html", line 149, in top-level template code
    {% block content %}{% endblock %}
  File "/Users/aryan/Documents/GitHub/job-bot-/app/templates/application/list.html", line 214, in block 'content'
    <h2 class="display-6">{{ "%.1f"|format(interview_rate) }}%</h2>
  File "/Users/aryan/opt/anaconda3/lib/python3.8/site-packages/jinja2/filters.py", line 1016, in do_format
    return soft_str(value) % (kwargs or args)
jinja2.exceptions.UndefinedError: 'interview_rate' is undefined
2025-06-23 20:24:31,804 ERROR: Exception on /dashboard [GET] [in /Users/aryan/opt/anaconda3/lib/python3.8/site-packages/flask/app.py:828]
Traceback (most recent call last):
  File "/Users/aryan/opt/anaconda3/lib/python3.8/site-packages/flask/app.py", line 1463, in wsgi_app
    response = self.full_dispatch_request()
  File "/Users/aryan/opt/anaconda3/lib/python3.8/site-packages/flask/app.py", line 872, in full_dispatch_request
    rv = self.handle_user_exception(e)
  File "/Users/aryan/opt/anaconda3/lib/python3.8/site-packages/flask/app.py", line 870, in full_dispatch_request
    rv = self.dispatch_request()
  File "/Users/aryan/opt/anaconda3/lib/python3.8/site-packages/flask/app.py", line 855, in dispatch_request
    return self.ensure_sync(self.view_functions[rule.endpoint])(**view_args)  # type: ignore[no-any-return]
  File "/Users/aryan/opt/anaconda3/lib/python3.8/site-packages/flask_login/utils.py", line 290, in decorated_view
    return current_app.ensure_sync(func)(*args, **kwargs)
  File "/Users/aryan/Documents/GitHub/job-bot-/app/routes.py", line 34, in dashboard
    return render_template('dashboard.html', title='Dashboard',
  File "/Users/aryan/opt/anaconda3/lib/python3.8/site-packages/flask/templating.py", line 150, in render_template
    return _render(app, template, context)
  File "/Users/aryan/opt/anaconda3/lib/python3.8/site-packages/flask/templating.py", line 131, in _render
    rv = template.render(context)
  File "/Users/aryan/opt/anaconda3/lib/python3.8/site-packages/jinja2/environment.py", line 1301, in render
    self.environment.handle_exception()
  File "/Users/aryan/opt/anaconda3/lib/python3.8/site-packages/jinja2/environment.py", line 936, in handle_exception
    raise rewrite_traceback_stack(source=source)
  File "/Users/aryan/Documents/GitHub/job-bot-/app/templates/dashboard.html", line 1, in top-level template code
    {% extends "base.html" %}
  File "/Users/aryan/Documents/GitHub/job-bot-/app/templates/base.html", line 149, in top-level template code
    {% block content %}{% endblock %}
  File "/Users/aryan/Documents/GitHub/job-bot-/app/templates/dashboard.html", line 33, in block 'content'
    <a href="{{ url_for('main.generate_cover_letter') }}" class="btn btn-info d-block py-3 text-white">
  File "/Users/aryan/opt/anaconda3/lib/python3.8/site-packages/flask/app.py", line 1074, in url_for
    return self.handle_url_build_error(error, endpoint, values)
  File "/Users/aryan/opt/anaconda3/lib/python3.8/site-packages/flask/app.py", line 1063, in url_for
    rv = url_adapter.build(  # type: ignore[union-attr]
  File "/Users/aryan/opt/anaconda3/lib/python3.8/site-packages/werkzeug/routing/map.py", line 919, in build
    raise BuildError(endpoint, values, method, self)
werkzeug.routing.exceptions.BuildError: Could not build url for endpoint 'main.generate_cover_letter'. Did you mean 'main.generate_cover_letter_api' instead?
2025-06-23 20:24:33,766 ERROR: Exception on /dashboard [GET] [in /Users/aryan/opt/anaconda3/lib/python3.8/site-packages/flask/app.py:828]
Traceback (most recent call last):
  File "/Users/aryan/opt/anaconda3/lib/python3.8/site-packages/flask/app.py", line 1463, in wsgi_app
    response = self.full_dispatch_request()
  File "/Users/aryan/opt/anaconda3/lib/python3.8/site-packages/flask/app.py", line 872, in full_dispatch_request
    rv = self.handle_user_exception(e)
  File "/Users/aryan/opt/anaconda3/lib/python3.8/site-packages/flask/app.py", line 870, in full_dispatch_request
    rv = self.dispatch_request()
  File "/Users/aryan/opt/anaconda3/lib/python3.8/site-packages/flask/app.py", line 855, in dispatch_request
    return self.ensure_sync(self.view_functions[rule.endpoint])(**view_args)  # type: ignore[no-any-return]
  File "/Users/aryan/opt/anaconda3/lib/python3.8/site-packages/flask_login/utils.py", line 290, in decorated_view
    return current_app.ensure_sync(func)(*args, **kwargs)
  File "/Users/aryan/Documents/GitHub/job-bot-/app/routes.py", line 34, in dashboard
    return render_template('dashboard.html', title='Dashboard',
  File "/Users/aryan/opt/anaconda3/lib/python3.8/site-packages/flask/templating.py", line 150, in render_template
    return _render(app, template, context)
  File "/Users/aryan/opt/anaconda3/lib/python3.8/site-packages/flask/templating.py", line 131, in _render
    rv = template.render(context)
  File "/Users/aryan/opt/anaconda3/lib/python3.8/site-packages/jinja2/environment.py", line 1301, in render
    self.environment.handle_exception()
  File "/Users/aryan/opt/anaconda3/lib/python3.8/site-packages/jinja2/environment.py", line 936, in handle_exception
    raise rewrite_traceback_stack(source=source)
  File "/Users/aryan/Documents/GitHub/job-bot-/app/templates/dashboard.html", line 1, in top-level template code
    {% extends "base.html" %}
  File "/Users/aryan/Documents/GitHub/job-bot-/app/templates/base.html", line 149, in top-level template code
    {% block content %}{% endblock %}
  File "/Users/aryan/Documents/GitHub/job-bot-/app/templates/dashboard.html", line 33, in block 'content'
    <a href="{{ url_for('main.generate_cover_letter') }}" class="btn btn-info d-block py-3 text-white">
  File "/Users/aryan/opt/anaconda3/lib/python3.8/site-packages/flask/app.py", line 1074, in url_for
    return self.handle_url_build_error(error, endpoint, values)
  File "/Users/aryan/opt/anaconda3/lib/python3.8/site-packages/flask/app.py", line 1063, in url_for
    rv = url_adapter.build(  # type: ignore[union-attr]
  File "/Users/aryan/opt/anaconda3/lib/python3.8/site-packages/werkzeug/routing/map.py", line 919, in build
    raise BuildError(endpoint, values, method, self)
werkzeug.routing.exceptions.BuildError: Could not build url for endpoint 'main.generate_cover_letter'. Did you mean 'main.generate_cover_letter_api' instead?
