2025-06-23 20:31:05,146 ERROR: Exception on /dashboard [GET] [in /Users/aryan/opt/anaconda3/lib/python3.8/site-packages/flask/app.py:828]
Traceback (most recent call last):
  File "/Users/aryan/opt/anaconda3/lib/python3.8/site-packages/flask/app.py", line 1463, in wsgi_app
    response = self.full_dispatch_request()
  File "/Users/aryan/opt/anaconda3/lib/python3.8/site-packages/flask/app.py", line 872, in full_dispatch_request
    rv = self.handle_user_exception(e)
  File "/Users/aryan/opt/anaconda3/lib/python3.8/site-packages/flask/app.py", line 870, in full_dispatch_request
    rv = self.dispatch_request()
  File "/Users/aryan/opt/anaconda3/lib/python3.8/site-packages/flask/app.py", line 855, in dispatch_request
    return self.ensure_sync(self.view_functions[rule.endpoint])(**view_args)  # type: ignore[no-any-return]
  File "/Users/aryan/opt/anaconda3/lib/python3.8/site-packages/flask_login/utils.py", line 290, in decorated_view
    return current_app.ensure_sync(func)(*args, **kwargs)
  File "/Users/aryan/Documents/GitHub/job-bot-/app/routes.py", line 50, in dashboard
    return render_template('dashboard.html', title='Dashboard',
  File "/Users/aryan/opt/anaconda3/lib/python3.8/site-packages/flask/templating.py", line 150, in render_template
    return _render(app, template, context)
  File "/Users/aryan/opt/anaconda3/lib/python3.8/site-packages/flask/templating.py", line 131, in _render
    rv = template.render(context)
  File "/Users/aryan/opt/anaconda3/lib/python3.8/site-packages/jinja2/environment.py", line 1301, in render
    self.environment.handle_exception()
  File "/Users/aryan/opt/anaconda3/lib/python3.8/site-packages/jinja2/environment.py", line 936, in handle_exception
    raise rewrite_traceback_stack(source=source)
  File "/Users/aryan/Documents/GitHub/job-bot-/app/templates/dashboard.html", line 1, in top-level template code
    {% extends "base.html" %}
  File "/Users/aryan/Documents/GitHub/job-bot-/app/templates/base.html", line 149, in top-level template code
    {% block content %}{% endblock %}
  File "/Users/aryan/Documents/GitHub/job-bot-/app/templates/dashboard.html", line 178, in block 'content'
    <a href="{{ url_for('main.interviews') }}" class="btn btn-outline-primary btn-sm">View All</a>
  File "/Users/aryan/opt/anaconda3/lib/python3.8/site-packages/flask/app.py", line 1074, in url_for
    return self.handle_url_build_error(error, endpoint, values)
  File "/Users/aryan/opt/anaconda3/lib/python3.8/site-packages/flask/app.py", line 1063, in url_for
    rv = url_adapter.build(  # type: ignore[union-attr]
  File "/Users/aryan/opt/anaconda3/lib/python3.8/site-packages/werkzeug/routing/map.py", line 919, in build
    raise BuildError(endpoint, values, method, self)
werkzeug.routing.exceptions.BuildError: Could not build url for endpoint 'main.interviews'. Did you mean 'main.index' instead?
2025-06-23 20:33:19,499 INFO: Job Bot startup [in /Users/aryan/Documents/GitHub/job-bot-/app/__init__.py:53]
2025-06-23 20:33:21,724 INFO: Database tables created successfully [in /Users/aryan/Documents/GitHub/job-bot-/app/__init__.py:59]
2025-06-23 20:33:41,920 ERROR: Exception on /resumes [GET] [in /Users/aryan/opt/anaconda3/lib/python3.8/site-packages/flask/app.py:828]
Traceback (most recent call last):
  File "/Users/aryan/opt/anaconda3/lib/python3.8/site-packages/flask/app.py", line 1463, in wsgi_app
    response = self.full_dispatch_request()
  File "/Users/aryan/opt/anaconda3/lib/python3.8/site-packages/flask/app.py", line 872, in full_dispatch_request
    rv = self.handle_user_exception(e)
  File "/Users/aryan/opt/anaconda3/lib/python3.8/site-packages/flask/app.py", line 870, in full_dispatch_request
    rv = self.dispatch_request()
  File "/Users/aryan/opt/anaconda3/lib/python3.8/site-packages/flask/app.py", line 855, in dispatch_request
    return self.ensure_sync(self.view_functions[rule.endpoint])(**view_args)  # type: ignore[no-any-return]
  File "/Users/aryan/opt/anaconda3/lib/python3.8/site-packages/flask_login/utils.py", line 290, in decorated_view
    return current_app.ensure_sync(func)(*args, **kwargs)
  File "/Users/aryan/Documents/GitHub/job-bot-/app/routes.py", line 58, in resumes
    return render_template('resume/list.html', resumes=resumes)
  File "/Users/aryan/opt/anaconda3/lib/python3.8/site-packages/flask/templating.py", line 150, in render_template
    return _render(app, template, context)
  File "/Users/aryan/opt/anaconda3/lib/python3.8/site-packages/flask/templating.py", line 131, in _render
    rv = template.render(context)
  File "/Users/aryan/opt/anaconda3/lib/python3.8/site-packages/jinja2/environment.py", line 1301, in render
    self.environment.handle_exception()
  File "/Users/aryan/opt/anaconda3/lib/python3.8/site-packages/jinja2/environment.py", line 936, in handle_exception
    raise rewrite_traceback_stack(source=source)
  File "/Users/aryan/Documents/GitHub/job-bot-/app/templates/resume/list.html", line 1, in top-level template code
    {% extends "base.html" %}
  File "/Users/aryan/Documents/GitHub/job-bot-/app/templates/base.html", line 149, in top-level template code
    {% block content %}{% endblock %}
  File "/Users/aryan/Documents/GitHub/job-bot-/app/templates/resume/list.html", line 45, in block 'content'
    <a href="{{ url_for('main.view_resume', id=resume.id) }}" class="btn btn-outline-primary btn-sm">
  File "/Users/aryan/opt/anaconda3/lib/python3.8/site-packages/flask/app.py", line 1074, in url_for
    return self.handle_url_build_error(error, endpoint, values)
  File "/Users/aryan/opt/anaconda3/lib/python3.8/site-packages/flask/app.py", line 1063, in url_for
    rv = url_adapter.build(  # type: ignore[union-attr]
  File "/Users/aryan/opt/anaconda3/lib/python3.8/site-packages/werkzeug/routing/map.py", line 919, in build
    raise BuildError(endpoint, values, method, self)
werkzeug.routing.exceptions.BuildError: Could not build url for endpoint 'main.view_resume' with values ['id']. Did you mean 'main.resumes' instead?
2025-06-23 20:34:54,293 ERROR: Exception on /api/analyze [POST] [in /Users/aryan/opt/anaconda3/lib/python3.8/site-packages/flask/app.py:828]
Traceback (most recent call last):
  File "/Users/aryan/opt/anaconda3/lib/python3.8/site-packages/flask/app.py", line 1463, in wsgi_app
    response = self.full_dispatch_request()
  File "/Users/aryan/opt/anaconda3/lib/python3.8/site-packages/flask/app.py", line 872, in full_dispatch_request
    rv = self.handle_user_exception(e)
  File "/Users/aryan/opt/anaconda3/lib/python3.8/site-packages/flask/app.py", line 870, in full_dispatch_request
    rv = self.dispatch_request()
  File "/Users/aryan/opt/anaconda3/lib/python3.8/site-packages/flask/app.py", line 855, in dispatch_request
    return self.ensure_sync(self.view_functions[rule.endpoint])(**view_args)  # type: ignore[no-any-return]
  File "/Users/aryan/opt/anaconda3/lib/python3.8/site-packages/flask_login/utils.py", line 290, in decorated_view
    return current_app.ensure_sync(func)(*args, **kwargs)
  File "/Users/aryan/Documents/GitHub/job-bot-/app/routes.py", line 197, in analyze
    analysis = analyze_job_description(data['job_description'], resume.content)
  File "/Users/aryan/Documents/GitHub/job-bot-/app/ai_utils.py", line 41, in analyze_job_description
    job_skills_response = openai.ChatCompletion.create(
  File "/Users/aryan/opt/anaconda3/lib/python3.8/site-packages/openai/lib/_old_api.py", line 39, in __call__
    raise APIRemovedInV1(symbol=self._symbol)
openai.lib._old_api.APIRemovedInV1: 

You tried to access openai.ChatCompletion, but this is no longer supported in openai>=1.0.0 - see the README at https://github.com/openai/openai-python for the API.

You can run `openai migrate` to automatically upgrade your codebase to use the 1.0.0 interface. 

Alternatively, you can pin your installation to the old version, e.g. `pip install openai==0.28`

A detailed migration guide is available here: https://github.com/openai/openai-python/discussions/742

2025-06-23 20:35:02,677 ERROR: Exception on /api/analyze [POST] [in /Users/aryan/opt/anaconda3/lib/python3.8/site-packages/flask/app.py:828]
Traceback (most recent call last):
  File "/Users/aryan/opt/anaconda3/lib/python3.8/site-packages/flask/app.py", line 1463, in wsgi_app
    response = self.full_dispatch_request()
  File "/Users/aryan/opt/anaconda3/lib/python3.8/site-packages/flask/app.py", line 872, in full_dispatch_request
    rv = self.handle_user_exception(e)
  File "/Users/aryan/opt/anaconda3/lib/python3.8/site-packages/flask/app.py", line 870, in full_dispatch_request
    rv = self.dispatch_request()
  File "/Users/aryan/opt/anaconda3/lib/python3.8/site-packages/flask/app.py", line 855, in dispatch_request
    return self.ensure_sync(self.view_functions[rule.endpoint])(**view_args)  # type: ignore[no-any-return]
  File "/Users/aryan/opt/anaconda3/lib/python3.8/site-packages/flask_login/utils.py", line 290, in decorated_view
    return current_app.ensure_sync(func)(*args, **kwargs)
  File "/Users/aryan/Documents/GitHub/job-bot-/app/routes.py", line 197, in analyze
    analysis = analyze_job_description(data['job_description'], resume.content)
  File "/Users/aryan/Documents/GitHub/job-bot-/app/ai_utils.py", line 41, in analyze_job_description
    job_skills_response = openai.ChatCompletion.create(
  File "/Users/aryan/opt/anaconda3/lib/python3.8/site-packages/openai/lib/_old_api.py", line 39, in __call__
    raise APIRemovedInV1(symbol=self._symbol)
openai.lib._old_api.APIRemovedInV1: 

You tried to access openai.ChatCompletion, but this is no longer supported in openai>=1.0.0 - see the README at https://github.com/openai/openai-python for the API.

You can run `openai migrate` to automatically upgrade your codebase to use the 1.0.0 interface. 

Alternatively, you can pin your installation to the old version, e.g. `pip install openai==0.28`

A detailed migration guide is available here: https://github.com/openai/openai-python/discussions/742

