2025-06-24 13:07:36,440 ERROR: Exception on /api/generate-cover-letter [POST] [in /Users/aryan/opt/anaconda3/lib/python3.8/site-packages/flask/app.py:828]
Traceback (most recent call last):
  File "/Users/aryan/opt/anaconda3/lib/python3.8/site-packages/flask/app.py", line 1463, in wsgi_app
    response = self.full_dispatch_request()
  File "/Users/aryan/opt/anaconda3/lib/python3.8/site-packages/flask/app.py", line 872, in full_dispatch_request
    rv = self.handle_user_exception(e)
  File "/Users/aryan/opt/anaconda3/lib/python3.8/site-packages/flask/app.py", line 870, in full_dispatch_request
    rv = self.dispatch_request()
  File "/Users/aryan/opt/anaconda3/lib/python3.8/site-packages/flask/app.py", line 855, in dispatch_request
    return self.ensure_sync(self.view_functions[rule.endpoint])(**view_args)  # type: ignore[no-any-return]
  File "/Users/aryan/opt/anaconda3/lib/python3.8/site-packages/flask_login/utils.py", line 290, in decorated_view
    return current_app.ensure_sync(func)(*args, **kwargs)
  File "/Users/aryan/Documents/GitHub/job-bot-/app/routes.py", line 212, in generate_cover_letter_api
    cover_letter = generate_cover_letter(data['job_description'], resume.content)
  File "/Users/aryan/opt/anaconda3/lib/python3.8/site-packages/flask_login/utils.py", line 290, in decorated_view
    return current_app.ensure_sync(func)(*args, **kwargs)
TypeError: generate_cover_letter() takes 0 positional arguments but 2 were given
2025-06-24 13:08:53,043 INFO: Job Bot startup [in /Users/aryan/Documents/GitHub/job-bot-/app/__init__.py:53]
2025-06-24 13:08:55,405 INFO: Database tables created successfully [in /Users/aryan/Documents/GitHub/job-bot-/app/__init__.py:59]
2025-06-24 13:10:35,312 ERROR: Exception on /application/new [POST] [in /Users/aryan/opt/anaconda3/lib/python3.8/site-packages/flask/app.py:828]
Traceback (most recent call last):
  File "/Users/aryan/opt/anaconda3/lib/python3.8/site-packages/flask/app.py", line 1463, in wsgi_app
    response = self.full_dispatch_request()
  File "/Users/aryan/opt/anaconda3/lib/python3.8/site-packages/flask/app.py", line 872, in full_dispatch_request
    rv = self.handle_user_exception(e)
  File "/Users/aryan/opt/anaconda3/lib/python3.8/site-packages/flask/app.py", line 870, in full_dispatch_request
    rv = self.dispatch_request()
  File "/Users/aryan/opt/anaconda3/lib/python3.8/site-packages/flask/app.py", line 855, in dispatch_request
    return self.ensure_sync(self.view_functions[rule.endpoint])(**view_args)  # type: ignore[no-any-return]
  File "/Users/aryan/opt/anaconda3/lib/python3.8/site-packages/flask_login/utils.py", line 290, in decorated_view
    return current_app.ensure_sync(func)(*args, **kwargs)
  File "/Users/aryan/Documents/GitHub/job-bot-/app/routes.py", line 124, in new_application
    application = JobApplication(
  File "<string>", line 4, in __init__
  File "/Users/aryan/opt/anaconda3/lib/python3.8/site-packages/sqlalchemy/orm/state.py", line 572, in _initialize_instance
    manager.dispatch.init_failure(self, args, kwargs)
  File "/Users/aryan/opt/anaconda3/lib/python3.8/site-packages/sqlalchemy/util/langhelpers.py", line 224, in __exit__
    raise exc_value.with_traceback(exc_tb)
  File "/Users/aryan/opt/anaconda3/lib/python3.8/site-packages/sqlalchemy/orm/state.py", line 569, in _initialize_instance
    manager.original_init(*mixed[1:], **kwargs)
  File "/Users/aryan/opt/anaconda3/lib/python3.8/site-packages/sqlalchemy/orm/decl_base.py", line 2176, in _declarative_constructor
    setattr(self, k, kwargs[k])
  File "/Users/aryan/opt/anaconda3/lib/python3.8/site-packages/sqlalchemy/orm/attributes.py", line 537, in __set__
    self.impl.set(
  File "/Users/aryan/opt/anaconda3/lib/python3.8/site-packages/sqlalchemy/orm/attributes.py", line 1467, in set
    value = self.fire_replace_event(state, dict_, value, old, initiator)
  File "/Users/aryan/opt/anaconda3/lib/python3.8/site-packages/sqlalchemy/orm/attributes.py", line 1506, in fire_replace_event
    value = fn(
  File "/Users/aryan/opt/anaconda3/lib/python3.8/site-packages/sqlalchemy/orm/attributes.py", line 2161, in emit_backref_from_scalar_set_event
    instance_state(child),
AttributeError: 'str' object has no attribute '_sa_instance_state'
2025-06-24 13:10:46,694 ERROR: Exception on /resumes [GET] [in /Users/aryan/opt/anaconda3/lib/python3.8/site-packages/flask/app.py:828]
Traceback (most recent call last):
  File "/Users/aryan/opt/anaconda3/lib/python3.8/site-packages/flask/app.py", line 1463, in wsgi_app
    response = self.full_dispatch_request()
  File "/Users/aryan/opt/anaconda3/lib/python3.8/site-packages/flask/app.py", line 872, in full_dispatch_request
    rv = self.handle_user_exception(e)
  File "/Users/aryan/opt/anaconda3/lib/python3.8/site-packages/flask/app.py", line 870, in full_dispatch_request
    rv = self.dispatch_request()
  File "/Users/aryan/opt/anaconda3/lib/python3.8/site-packages/flask/app.py", line 855, in dispatch_request
    return self.ensure_sync(self.view_functions[rule.endpoint])(**view_args)  # type: ignore[no-any-return]
  File "/Users/aryan/opt/anaconda3/lib/python3.8/site-packages/flask_login/utils.py", line 290, in decorated_view
    return current_app.ensure_sync(func)(*args, **kwargs)
  File "/Users/aryan/Documents/GitHub/job-bot-/app/routes.py", line 58, in resumes
    return render_template('resume/list.html', resumes=resumes)
  File "/Users/aryan/opt/anaconda3/lib/python3.8/site-packages/flask/templating.py", line 150, in render_template
    return _render(app, template, context)
  File "/Users/aryan/opt/anaconda3/lib/python3.8/site-packages/flask/templating.py", line 131, in _render
    rv = template.render(context)
  File "/Users/aryan/opt/anaconda3/lib/python3.8/site-packages/jinja2/environment.py", line 1301, in render
    self.environment.handle_exception()
  File "/Users/aryan/opt/anaconda3/lib/python3.8/site-packages/jinja2/environment.py", line 936, in handle_exception
    raise rewrite_traceback_stack(source=source)
  File "/Users/aryan/Documents/GitHub/job-bot-/app/templates/resume/list.html", line 1, in top-level template code
    {% extends "base.html" %}
  File "/Users/aryan/Documents/GitHub/job-bot-/app/templates/base.html", line 149, in top-level template code
    {% block content %}{% endblock %}
  File "/Users/aryan/Documents/GitHub/job-bot-/app/templates/resume/list.html", line 46, in block 'content'
    <a href="{{ url_for('main.edit_resume', id=resume.id) }}" class="btn btn-outline-secondary btn-sm">
  File "/Users/aryan/opt/anaconda3/lib/python3.8/site-packages/flask/app.py", line 1074, in url_for
    return self.handle_url_build_error(error, endpoint, values)
  File "/Users/aryan/opt/anaconda3/lib/python3.8/site-packages/flask/app.py", line 1063, in url_for
    rv = url_adapter.build(  # type: ignore[union-attr]
  File "/Users/aryan/opt/anaconda3/lib/python3.8/site-packages/werkzeug/routing/map.py", line 919, in build
    raise BuildError(endpoint, values, method, self)
werkzeug.routing.exceptions.BuildError: Could not build url for endpoint 'main.edit_resume' with values ['id']. Did you mean 'main.view_resume' instead?
2025-06-24 13:14:33,030 ERROR: Exception on /dashboard [GET] [in /Users/aryan/opt/anaconda3/lib/python3.8/site-packages/flask/app.py:828]
Traceback (most recent call last):
  File "/Users/aryan/opt/anaconda3/lib/python3.8/site-packages/flask/app.py", line 1463, in wsgi_app
    response = self.full_dispatch_request()
  File "/Users/aryan/opt/anaconda3/lib/python3.8/site-packages/flask/app.py", line 872, in full_dispatch_request
    rv = self.handle_user_exception(e)
  File "/Users/aryan/opt/anaconda3/lib/python3.8/site-packages/flask/app.py", line 870, in full_dispatch_request
    rv = self.dispatch_request()
  File "/Users/aryan/opt/anaconda3/lib/python3.8/site-packages/flask/app.py", line 855, in dispatch_request
    return self.ensure_sync(self.view_functions[rule.endpoint])(**view_args)  # type: ignore[no-any-return]
  File "/Users/aryan/opt/anaconda3/lib/python3.8/site-packages/flask_login/utils.py", line 290, in decorated_view
    return current_app.ensure_sync(func)(*args, **kwargs)
  File "/Users/aryan/Documents/GitHub/job-bot-/app/routes.py", line 50, in dashboard
    return render_template('dashboard.html', title='Dashboard',
  File "/Users/aryan/opt/anaconda3/lib/python3.8/site-packages/flask/templating.py", line 150, in render_template
    return _render(app, template, context)
  File "/Users/aryan/opt/anaconda3/lib/python3.8/site-packages/flask/templating.py", line 131, in _render
    rv = template.render(context)
  File "/Users/aryan/opt/anaconda3/lib/python3.8/site-packages/jinja2/environment.py", line 1301, in render
    self.environment.handle_exception()
  File "/Users/aryan/opt/anaconda3/lib/python3.8/site-packages/jinja2/environment.py", line 936, in handle_exception
    raise rewrite_traceback_stack(source=source)
  File "/Users/aryan/Documents/GitHub/job-bot-/app/templates/dashboard.html", line 1, in top-level template code
    {% extends "base.html" %}
  File "/Users/aryan/Documents/GitHub/job-bot-/app/templates/base.html", line 149, in top-level template code
    {% block content %}{% endblock %}
  File "/Users/aryan/Documents/GitHub/job-bot-/app/templates/dashboard.html", line 33, in block 'content'
    <a href="{{ url_for('main.generate_cover_letter') }}" class="btn btn-info d-block py-3 text-white">
  File "/Users/aryan/opt/anaconda3/lib/python3.8/site-packages/flask/app.py", line 1074, in url_for
    return self.handle_url_build_error(error, endpoint, values)
  File "/Users/aryan/opt/anaconda3/lib/python3.8/site-packages/flask/app.py", line 1063, in url_for
    rv = url_adapter.build(  # type: ignore[union-attr]
  File "/Users/aryan/opt/anaconda3/lib/python3.8/site-packages/werkzeug/routing/map.py", line 919, in build
    raise BuildError(endpoint, values, method, self)
werkzeug.routing.exceptions.BuildError: Could not build url for endpoint 'main.generate_cover_letter'. Did you mean 'main.generate_cover_letter_api' instead?
